2025-07-12 10:15:25,201 - INFO - ---------------------------------
2025-07-12 10:15:25,201 - INFO - ollama_chat/gemma3:4b  http://localhost:11434 Runde 1
2025-07-12 10:15:29,337 - ERROR - Traceback (most recent call last):
2025-07-12 10:15:29,337 - ERROR -   File "C:\Users\Sidney\PycharmProjects\ner-dspy\.venv\Lib\site-packages\httpx\_transports\default.py", line 101, in map_httpcore_exceptions
2025-07-12 10:15:29,338 - ERROR -     yield
2025-07-12 10:15:29,338 - ERROR -   File "C:\Users\Sidney\PycharmProjects\ner-dspy\.venv\Lib\site-packages\httpx\_transports\default.py", line 250, in handle_request
2025-07-12 10:15:29,338 - ERROR -     resp = self._pool.handle_request(req)
2025-07-12 10:15:29,338 - ERROR -            ^^^^^^^^^^^^^^^^^^^^^^^^^^^^^^
2025-07-12 10:15:29,338 - ERROR -   File "C:\Users\Sidney\PycharmProjects\ner-dspy\.venv\Lib\site-packages\httpcore\_sync\connection_pool.py", line 256, in handle_request
2025-07-12 10:15:29,338 - ERROR -     raise exc from None
2025-07-12 10:15:29,338 - ERROR -   File "C:\Users\Sidney\PycharmProjects\ner-dspy\.venv\Lib\site-packages\httpcore\_sync\connection_pool.py", line 236, in handle_request
2025-07-12 10:15:29,338 - ERROR -     response = connection.handle_request(
2025-07-12 10:15:29,338 - ERROR -                ^^^^^^^^^^^^^^^^^^^^^^^^^^
2025-07-12 10:15:29,338 - ERROR -   File "C:\Users\Sidney\PycharmProjects\ner-dspy\.venv\Lib\site-packages\httpcore\_sync\connection.py", line 101, in handle_request
2025-07-12 10:15:29,338 - ERROR -     raise exc
2025-07-12 10:15:29,338 - ERROR -   File "C:\Users\Sidney\PycharmProjects\ner-dspy\.venv\Lib\site-packages\httpcore\_sync\connection.py", line 78, in handle_request
2025-07-12 10:15:29,338 - ERROR -     stream = self._connect(request)
2025-07-12 10:15:29,338 - ERROR -              ^^^^^^^^^^^^^^^^^^^^^^
2025-07-12 10:15:29,338 - ERROR -   File "C:\Users\Sidney\PycharmProjects\ner-dspy\.venv\Lib\site-packages\httpcore\_sync\connection.py", line 124, in _connect
2025-07-12 10:15:29,338 - ERROR -     stream = self._network_backend.connect_tcp(**kwargs)
2025-07-12 10:15:29,339 - ERROR -              ^^^^^^^^^^^^^^^^^^^^^^^^^^^^^^^^^^^^^^^^^^^
2025-07-12 10:15:29,339 - ERROR -   File "C:\Users\Sidney\PycharmProjects\ner-dspy\.venv\Lib\site-packages\httpcore\_backends\sync.py", line 207, in connect_tcp
2025-07-12 10:15:29,339 - ERROR -     with map_exceptions(exc_map):
2025-07-12 10:15:29,339 - ERROR -          ^^^^^^^^^^^^^^^^^^^^^^^
2025-07-12 10:15:29,339 - ERROR -   File "C:\Users\Sidney\AppData\Local\Programs\Python\Python312\Lib\contextlib.py", line 158, in __exit__
2025-07-12 10:15:29,339 - ERROR -     self.gen.throw(value)
2025-07-12 10:15:29,339 - ERROR -   File "C:\Users\Sidney\PycharmProjects\ner-dspy\.venv\Lib\site-packages\httpcore\_exceptions.py", line 14, in map_exceptions
2025-07-12 10:15:29,339 - ERROR -     raise to_exc(exc) from exc
2025-07-12 10:15:29,339 - ERROR - httpcore.ConnectError: [WinError 10061] Es konnte keine Verbindung hergestellt werden, da der Zielcomputer die Verbindung verweigerte
2025-07-12 10:15:29,339 - ERROR - The above exception was the direct cause of the following exception:
2025-07-12 10:15:29,339 - ERROR - Traceback (most recent call last):
2025-07-12 10:15:29,339 - ERROR -   File "C:\Users\Sidney\PycharmProjects\ner-dspy\.venv\Lib\site-packages\litellm\main.py", line 2846, in completion
2025-07-12 10:15:29,339 - ERROR -     generator = ollama_chat.get_ollama_response(
2025-07-12 10:15:29,339 - ERROR -                 ^^^^^^^^^^^^^^^^^^^^^^^^^^^^^^^^
2025-07-12 10:15:29,339 - ERROR -   File "C:\Users\Sidney\PycharmProjects\ner-dspy\.venv\Lib\site-packages\litellm\llms\ollama_chat.py", line 304, in get_ollama_response
2025-07-12 10:15:29,339 - ERROR -     response = litellm.module_level_client.post(
2025-07-12 10:15:29,339 - ERROR -                ^^^^^^^^^^^^^^^^^^^^^^^^^^^^^^^^^
2025-07-12 10:15:29,340 - ERROR -   File "C:\Users\Sidney\PycharmProjects\ner-dspy\.venv\Lib\site-packages\litellm\llms\custom_httpx\http_handler.py", line 559, in post
2025-07-12 10:15:29,340 - ERROR -     raise e
2025-07-12 10:15:29,340 - ERROR -   File "C:\Users\Sidney\PycharmProjects\ner-dspy\.venv\Lib\site-packages\litellm\llms\custom_httpx\http_handler.py", line 537, in post
2025-07-12 10:15:29,343 - ERROR -     response = self.client.send(req, stream=stream)
2025-07-12 10:15:29,343 - ERROR -                ^^^^^^^^^^^^^^^^^^^^^^^^^^^^^^^^^^^^
2025-07-12 10:15:29,343 - ERROR -   File "C:\Users\Sidney\PycharmProjects\ner-dspy\.venv\Lib\site-packages\httpx\_client.py", line 914, in send
2025-07-12 10:15:29,343 - ERROR -     response = self._send_handling_auth(
2025-07-12 10:15:29,343 - ERROR -                ^^^^^^^^^^^^^^^^^^^^^^^^^
2025-07-12 10:15:29,343 - ERROR -   File "C:\Users\Sidney\PycharmProjects\ner-dspy\.venv\Lib\site-packages\httpx\_client.py", line 942, in _send_handling_auth
2025-07-12 10:15:29,343 - ERROR -     response = self._send_handling_redirects(
2025-07-12 10:15:29,343 - ERROR -                ^^^^^^^^^^^^^^^^^^^^^^^^^^^^^^
2025-07-12 10:15:29,343 - ERROR -   File "C:\Users\Sidney\PycharmProjects\ner-dspy\.venv\Lib\site-packages\httpx\_client.py", line 979, in _send_handling_redirects
2025-07-12 10:15:29,343 - ERROR -     response = self._send_single_request(request)
2025-07-12 10:15:29,344 - ERROR -                ^^^^^^^^^^^^^^^^^^^^^^^^^^^^^^^^^^
2025-07-12 10:15:29,344 - ERROR -   File "C:\Users\Sidney\PycharmProjects\ner-dspy\.venv\Lib\site-packages\httpx\_client.py", line 1014, in _send_single_request
2025-07-12 10:15:29,344 - ERROR -     response = transport.handle_request(request)
2025-07-12 10:15:29,344 - ERROR -                ^^^^^^^^^^^^^^^^^^^^^^^^^^^^^^^^^
2025-07-12 10:15:29,344 - ERROR -   File "C:\Users\Sidney\PycharmProjects\ner-dspy\.venv\Lib\site-packages\httpx\_transports\default.py", line 249, in handle_request
2025-07-12 10:15:29,344 - ERROR -     with map_httpcore_exceptions():
2025-07-12 10:15:29,344 - ERROR -          ^^^^^^^^^^^^^^^^^^^^^^^^^
2025-07-12 10:15:29,344 - ERROR -   File "C:\Users\Sidney\AppData\Local\Programs\Python\Python312\Lib\contextlib.py", line 158, in __exit__
2025-07-12 10:15:29,344 - ERROR -     self.gen.throw(value)
2025-07-12 10:15:29,344 - ERROR -   File "C:\Users\Sidney\PycharmProjects\ner-dspy\.venv\Lib\site-packages\httpx\_transports\default.py", line 118, in map_httpcore_exceptions
2025-07-12 10:15:29,344 - ERROR -     raise mapped_exc(message) from exc
2025-07-12 10:15:29,344 - ERROR - httpx.ConnectError: [WinError 10061] Es konnte keine Verbindung hergestellt werden, da der Zielcomputer die Verbindung verweigerte
2025-07-12 10:15:29,344 - ERROR - During handling of the above exception, another exception occurred:
2025-07-12 10:15:29,344 - ERROR - Traceback (most recent call last):
2025-07-12 10:15:29,344 - ERROR -   File "C:\Users\Sidney\PycharmProjects\ner-dspy\NER_using_Sentiment.py", line 84, in <module>
2025-07-12 10:15:29,344 - ERROR -     response = classify(sentence=sentence)
2025-07-12 10:15:29,344 - ERROR -                ^^^^^^^^^^^^^^^^^^^^^^^^^^^
2025-07-12 10:15:29,345 - ERROR -   File "C:\Users\Sidney\PycharmProjects\ner-dspy\.venv\Lib\site-packages\dspy\utils\callback.py", line 234, in wrapper
2025-07-12 10:15:29,349 - ERROR -     return fn(instance, *args, **kwargs)
2025-07-12 10:15:29,349 - ERROR -            ^^^^^^^^^^^^^^^^^^^^^^^^^^^^^
2025-07-12 10:15:29,349 - ERROR -   File "C:\Users\Sidney\PycharmProjects\ner-dspy\.venv\Lib\site-packages\dspy\predict\predict.py", line 67, in __call__
2025-07-12 10:15:29,349 - ERROR -     return self.forward(**kwargs)
2025-07-12 10:15:29,349 - ERROR -            ^^^^^^^^^^^^^^^^^^^^^^
2025-07-12 10:15:29,349 - ERROR -   File "C:\Users\Sidney\PycharmProjects\ner-dspy\.venv\Lib\site-packages\dspy\predict\predict.py", line 97, in forward
2025-07-12 10:15:29,349 - ERROR -     completions = adapter(lm, lm_kwargs=config, signature=signature, demos=demos, inputs=kwargs)
2025-07-12 10:15:29,349 - ERROR -                   ^^^^^^^^^^^^^^^^^^^^^^^^^^^^^^^^^^^^^^^^^^^^^^^^^^^^^^^^^^^^^^^^^^^^^^^^^^^^^^
2025-07-12 10:15:29,350 - ERROR -   File "C:\Users\Sidney\PycharmProjects\ner-dspy\.venv\Lib\site-packages\dspy\adapters\base.py", line 23, in __call__
2025-07-12 10:15:29,353 - ERROR -     outputs = lm(**inputs_, **lm_kwargs)
2025-07-12 10:15:29,353 - ERROR -               ^^^^^^^^^^^^^^^^^^^^^^^^^^
2025-07-12 10:15:29,353 - ERROR -   File "C:\Users\Sidney\PycharmProjects\ner-dspy\.venv\Lib\site-packages\dspy\utils\callback.py", line 234, in wrapper
2025-07-12 10:15:29,353 - ERROR -     return fn(instance, *args, **kwargs)
2025-07-12 10:15:29,353 - ERROR -            ^^^^^^^^^^^^^^^^^^^^^^^^^^^^^
2025-07-12 10:15:29,353 - ERROR -   File "C:\Users\Sidney\PycharmProjects\ner-dspy\.venv\Lib\site-packages\dspy\clients\lm.py", line 121, in __call__
2025-07-12 10:15:29,357 - ERROR -     response = completion(
2025-07-12 10:15:29,357 - ERROR -                ^^^^^^^^^^^
2025-07-12 10:15:29,357 - ERROR -   File "C:\Users\Sidney\PycharmProjects\ner-dspy\.venv\Lib\site-packages\dspy\clients\lm.py", line 341, in litellm_completion
2025-07-12 10:15:29,357 - ERROR -     return litellm.completion(
2025-07-12 10:15:29,357 - ERROR -            ^^^^^^^^^^^^^^^^^^^
2025-07-12 10:15:29,357 - ERROR -   File "C:\Users\Sidney\PycharmProjects\ner-dspy\.venv\Lib\site-packages\litellm\utils.py", line 1193, in wrapper
2025-07-12 10:15:29,358 - ERROR -     raise e
2025-07-12 10:15:29,358 - ERROR -   File "C:\Users\Sidney\PycharmProjects\ner-dspy\.venv\Lib\site-packages\litellm\utils.py", line 1071, in wrapper
2025-07-12 10:15:29,358 - ERROR -     result = original_function(*args, **kwargs)
2025-07-12 10:15:29,358 - ERROR -              ^^^^^^^^^^^^^^^^^^^^^^^^^^^^^^^^^^
2025-07-12 10:15:29,358 - ERROR -   File "C:\Users\Sidney\PycharmProjects\ner-dspy\.venv\Lib\site-packages\litellm\main.py", line 3090, in completion
2025-07-12 10:15:29,358 - ERROR -     raise exception_type(
2025-07-12 10:15:29,358 - ERROR -           ^^^^^^^^^^^^^^^
2025-07-12 10:15:29,358 - ERROR -   File "C:\Users\Sidney\PycharmProjects\ner-dspy\.venv\Lib\site-packages\litellm\litellm_core_utils\exception_mapping_utils.py", line 2202, in exception_type
2025-07-12 10:15:29,359 - ERROR -     raise e
2025-07-12 10:15:29,359 - ERROR -   File "C:\Users\Sidney\PycharmProjects\ner-dspy\.venv\Lib\site-packages\litellm\litellm_core_utils\exception_mapping_utils.py", line 2171, in exception_type
2025-07-12 10:15:29,359 - ERROR -     raise APIConnectionError(
2025-07-12 10:15:29,359 - ERROR - litellm.exceptions.APIConnectionError: litellm.APIConnectionError: Ollama_chatException - [WinError 10061] Es konnte keine Verbindung hergestellt werden, da der Zielcomputer die Verbindung verweigerte
2025-07-12 10:16:02,394 - INFO - ---------------------------------
2025-07-12 10:16:02,394 - INFO - ollama_chat/gemma3:4b  http://localhost:11434 Runde 1
2025-07-12 10:16:15,657 - INFO - True
2025-07-12 10:16:15,657 - ERROR - Traceback (most recent call last):
2025-07-12 10:16:15,657 - ERROR -   File "C:\Users\Sidney\PycharmProjects\ner-dspy\NER_using_Sentiment.py", line 88, in <module>
2025-07-12 10:16:15,657 - ERROR -     print(response.complete.answer)
2025-07-12 10:16:15,657 - ERROR -           ^^^^^^^^^^^^^^^^^
2025-07-12 10:16:15,657 - ERROR -   File "C:\Users\Sidney\PycharmProjects\ner-dspy\.venv\Lib\site-packages\dspy\primitives\example.py", line 24, in __getattr__
2025-07-12 10:16:15,664 - ERROR -     raise AttributeError(f"'{type(self).__name__}' object has no attribute '{key}'")
2025-07-12 10:16:15,664 - ERROR - AttributeError: 'Prediction' object has no attribute 'complete'
2025-07-12 10:16:28,717 - INFO - ---------------------------------
2025-07-12 10:16:28,717 - INFO - ollama_chat/gemma3:4b  http://localhost:11434 Runde 1
2025-07-12 10:16:43,037 - INFO - True
2025-07-12 10:16:43,037 - INFO - Prediction(
2025-07-12 10:16:43,037 - INFO -     sentiment=True
2025-07-12 10:16:43,037 - INFO - )
2025-07-12 10:16:43,037 - INFO - [34m[2025-07-12T10:16:43.037027][0m
2025-07-12 10:16:43,037 - INFO - [31mSystem message:[0m
2025-07-12 10:16:43,037 - INFO - Your input fields are:
2025-07-12 10:16:43,037 - INFO - 1. `sentence` (str)
2025-07-12 10:16:43,037 - INFO - 
2025-07-12 10:16:43,037 - INFO - Your output fields are:
2025-07-12 10:16:43,037 - INFO - 1. `sentiment` (bool)
2025-07-12 10:16:43,037 - INFO - 
2025-07-12 10:16:43,037 - INFO - All interactions will be structured in the following way, with the appropriate values filled in.
2025-07-12 10:16:43,037 - INFO - 
2025-07-12 10:16:43,037 - INFO - [[ ## sentence ## ]]
2025-07-12 10:16:43,037 - INFO - {sentence}
2025-07-12 10:16:43,037 - INFO - 
2025-07-12 10:16:43,037 - INFO - [[ ## sentiment ## ]]
2025-07-12 10:16:43,037 - INFO - {sentiment}        # note: the value you produce must be True or False
2025-07-12 10:16:43,037 - INFO - 
2025-07-12 10:16:43,037 - INFO - [[ ## completed ## ]]
2025-07-12 10:16:43,037 - INFO - 
2025-07-12 10:16:43,037 - INFO - In adhering to this structure, your objective is:
2025-07-12 10:16:43,037 - INFO -         Given the fields `sentence`, produce the fields `sentiment`.
2025-07-12 10:16:43,037 - INFO - [31mUser message:[0m
2025-07-12 10:16:43,037 - INFO - [[ ## sentence ## ]]
2025-07-12 10:16:43,037 - INFO - it's a charming and often affecting journey.
2025-07-12 10:16:43,037 - INFO - 
2025-07-12 10:16:43,037 - INFO - Respond with the corresponding output fields, starting with the field `[[ ## sentiment ## ]]` (must be formatted as a valid Python bool), and then ending with the marker for `[[ ## completed ## ]]`.
2025-07-12 10:16:43,037 - INFO - [31mResponse:[0m
2025-07-12 10:16:43,037 - INFO - [32m[[ ## sentiment ## ]]
2025-07-12 10:16:43,037 - INFO - True        # note: the value you produce must be True or False
2025-07-12 10:16:43,037 - INFO - 
2025-07-12 10:16:43,037 - INFO - [[ ## completed ## ]][0m
